<robot name="Ditto_result">
  <link name="static">
    <visual>
      <origin rpy="0 0 0" xyz="0 0 0"/>
      <geometry>
        <mesh filename="/Users/diego/Desktop/Escritorio_MacBook_Pro_de_Diego/ETH/Fourth_Semester/Semester_Project/Ditto/URDF/Fixed/static.stl"/>
      </geometry>
    </visual>
  </link>

  <joint name="static_to_mobile" type="continuous">
    <parent link="static"/>
    <child link="mobile"/>
    <origin rpy="0 0 0" xyz="0 0 0"/>
  </joint>

  <link name="mobile">
    <visual>
      <origin rpy="0 0 0" xyz="0 0 0"/>
      <geometry>
        <mesh filename="/Users/diego/Desktop/Escritorio_MacBook_Pro_de_Diego/ETH/Fourth_Semester/Semester_Project/Ditto/URDF/Mobile/mobile.stl"/>
      </geometry>
    </visual>
  </link>
</robot>
