<?xml version='1.0' encoding='UTF-8'?>
<robot name="Ditto_result">
  <link name="static">
    <inertial>
      <origin xyz="0.0 0.0 0.0" rpy="0.0 -0.0 0.0"/>
      <mass value="1.0"/>
      <inertia ixx="1.0" ixy="0.0" ixz="0.0" iyy="1.0" iyz="0.0" izz="1.0"/>
    </inertial>
    <visual>
      <geometry>
        <mesh filename="/Users/diego/Desktop/Escritorio_MacBook_Pro_de_Diego/ETH/Fourth_Semester/Semester_Project/Ditto/URDF/Fixed/static.stl"/>
      </geometry>
      <origin xyz="0.0 0.0 0.0" rpy="0.0 0.0 0.0"/>
    </visual>
  </link>
  <link name="mobile">
    <inertial>
      <origin xyz="0.0 0.0 0.0" rpy="0.0 -0.0 0.0"/>
      <mass value="1.0"/>
      <inertia ixx="1.0" ixy="0.0" ixz="0.0" iyy="1.0" iyz="0.0" izz="1.0"/>
    </inertial>
    <visual>
      <geometry>
        <mesh filename="/Users/diego/Desktop/Escritorio_MacBook_Pro_de_Diego/ETH/Fourth_Semester/Semester_Project/Ditto/URDF/Mobile/mobile.stl"/>
      </geometry>
      <origin xyz="-0.00448940917408759 0.16912831985062038 -0.06818164958201145" rpy="1.5789849393026034 0.9073537314239938 -3.1311995307110543"/>
    </visual>
  </link>
  <joint name="static_to_mobile" type="continuous">
    <parent link="static"/>
    <child link="mobile"/>
    <axis xyz="1. 0. 0."/>
    <origin xyz="-0.05648447573184967 0.03953160345554352 -0.16887876391410828" rpy="1.5758391475158768 0.0039413997619962594 -2.2342027819359687"/>
  </joint>
</robot>
